<?xml version='1.0' encoding='utf-8'?>
<sdf version="1.9">
  <model name="cable">
    <link name="cable_end_0">
      <pose>0.000000 0.000000 0.000000 0.000000 0.000000 0.000000</pose>
      <inertial>
        <pose>0 0 0 0 0 0</pose>
        <mass>0.0025000000000000001</mass>
        <inertia>
          <ixx>1e-03</ixx>
          <ixy>0</ixy>
          <ixz>0</ixz>
          <iyy>1e-03</iyy>
          <iyz>0</iyz>
          <izz>1e-03</izz>
        </inertia>
      </inertial>
      <collision name="base_collision">
        <pose>0 0 0 0 0 0</pose>
        <geometry>
          <sphere>
            <radius>0.002</radius>
          </sphere>
        </geometry>
        <surface>
          <friction>
            <torsional>
              <coefficient>0.05</coefficient>
            </torsional>
            <bullet>
              <friction>0.05</friction>
              <friction2>0.05</friction2>
            </bullet>
          </friction>
        </surface>
      </collision>
      <visual name="base_vis">
        <pose>0 0 0 0 0 0</pose>
        <geometry>
          <sphere>
            <radius>0.002</radius>
          </sphere>
        </geometry>
        <material>
          <diffuse>1 0.219999999 0 1</diffuse>
          <specular>0.5 0.5 0.5 1</specular>
          <pbr>
            <metal>
              <roughness>0.01</roughness>
              <metalness>0.01</metalness>
            </metal>
          </pbr>
        </material>
      </visual>
      <enable_wind>false</enable_wind>
    </link>
    <joint name="joint_end_0" type="ball">
      <pose>0.000000 0.000000 -0.024000 0.000000 0.000000 0.000000</pose>
      <child>link_1</child>
      <parent>cable_end_0</parent>
      <axis>
        <xyz>1.9813201779109516e-16 -1.5504091066542707e-17 1</xyz>
        <limit>
          <lower>-inf</lower>
          <upper>inf</upper>
          <effort>inf</effort>
          <velocity>inf</velocity>
          <stiffness>100000000</stiffness>
          <dissipation>1</dissipation>
        </limit>
        <dynamics>
          <spring_reference>0</spring_reference>
          <spring_stiffness>0</spring_stiffness>
          <damping>0.2</damping>
          <friction>0</friction>
        </dynamics>
      </axis>
    </joint>
    <link name="link_1">
      <pose>0.024000 0.000000 0.000000 0.000000 1.570790 0.000000</pose>
      <inertial>
        <pose>0 0 0 0 0 0</pose>
        <mass>0.0025000000000000001</mass>
        <inertia>
          <ixx>1e-03</ixx>
          <ixy>0</ixy>
          <ixz>0</ixz>
          <iyy>1e-03</iyy>
          <iyz>0</iyz>
          <izz>1e-03</izz>
        </inertia>
      </inertial>
      <collision name="link_1_collision">
        <pose>0 0 0 0 0 0</pose>
        <geometry>
          <cylinder>
            <length>0.048000000000000001</length>
            <radius>0.002</radius>
          </cylinder>
        </geometry>
        <surface>
          <friction>
            <torsional>
              <coefficient>0.05</coefficient>
            </torsional>
            <bullet>
              <friction>0.05</friction>
              <friction2>0.05</friction2>
            </bullet>
          </friction>
        </surface>
      </collision>
      <visual name="link_1_vis">
        <pose>0 0 0 0 0 0</pose>
        <geometry>
          <cylinder>
            <length>0.048000000000000001</length>
            <radius>0.002</radius>
          </cylinder>
        </geometry>
        <material>
          <diffuse>1 0.219999999 0 1</diffuse>
          <specular>0.5 0.5 0.5 1</specular>
          <pbr>
            <metal>
              <roughness>0.01</roughness>
              <metalness>0.01</metalness>
            </metal>
          </pbr>
        </material>
      </visual>
      <collision name="sphere_1_collision">
        <pose>0 0 0.024 0 0 0</pose>
        <geometry>
          <sphere>
            <radius>0.002</radius>
          </sphere>
        </geometry>
        <surface>
          <friction>
            <torsional>
              <coefficient>0.05</coefficient>
            </torsional>
            <bullet>
              <friction>0.05</friction>
              <friction2>0.05</friction2>
            </bullet>
          </friction>
        </surface>
      </collision>
      <visual name="sphere_1_vis">
        <pose>0 0 0.024 0 0 0</pose>
        <geometry>
          <sphere>
            <radius>0.002</radius>
          </sphere>
        </geometry>
        <material>
          <diffuse>1 0.219999999 0 1</diffuse>
          <specular>0.5 0.5 0.5 1</specular>
          <pbr>
            <metal>
              <roughness>0.01</roughness>
              <metalness>0.01</metalness>
            </metal>
          </pbr>
        </material>
      </visual>
      <enable_wind>false</enable_wind>
    </link>
    <link name="link_2">
      <pose>0.072000 0.000000 0.000000 0.000000 1.570790 0.000000</pose>
      <inertial>
        <pose>0 0 0 0 0 0</pose>
        <mass>0.0025000000000000001</mass>
        <inertia>
          <ixx>1e-03</ixx>
          <ixy>0</ixy>
          <ixz>0</ixz>
          <iyy>1e-03</iyy>
          <iyz>0</iyz>
          <izz>1e-03</izz>
        </inertia>
      </inertial>
      <collision name="link_2_collision">
        <pose>0 0 0 0 0 0</pose>
        <geometry>
          <cylinder>
            <length>0.048000000000000001</length>
            <radius>0.002</radius>
          </cylinder>
        </geometry>
        <surface>
          <friction>
            <torsional>
              <coefficient>0.05</coefficient>
            </torsional>
            <bullet>
              <friction>0.05</friction>
              <friction2>0.05</friction2>
            </bullet>
          </friction>
        </surface>
      </collision>
      <visual name="link_2_vis">
        <pose>0 0 0 0 0 0</pose>
        <geometry>
          <cylinder>
            <length>0.048000000000000001</length>
            <radius>0.002</radius>
          </cylinder>
        </geometry>
        <material>
          <diffuse>1 0.219999999 0 1</diffuse>
          <specular>0.5 0.5 0.5 1</specular>
          <pbr>
            <metal>
              <roughness>0.01</roughness>
              <metalness>0.01</metalness>
            </metal>
          </pbr>
        </material>
      </visual>
      <collision name="sphere_2_collision">
        <pose>0 0 0.024 0 0 0</pose>
        <geometry>
          <sphere>
            <radius>0.002</radius>
          </sphere>
        </geometry>
        <surface>
          <friction>
            <torsional>
              <coefficient>0.05</coefficient>
            </torsional>
            <bullet>
              <friction>0.05</friction>
              <friction2>0.05</friction2>
            </bullet>
          </friction>
        </surface>
      </collision>
      <visual name="sphere_2_vis">
        <pose>0 0 0.024 0 0 0</pose>
        <geometry>
          <sphere>
            <radius>0.002</radius>
          </sphere>
        </geometry>
        <material>
          <diffuse>1 0.219999999 0 1</diffuse>
          <specular>0.5 0.5 0.5 1</specular>
          <pbr>
            <metal>
              <roughness>0.01</roughness>
              <metalness>0.01</metalness>
            </metal>
          </pbr>
        </material>
      </visual>
      <enable_wind>false</enable_wind>
    </link>
    <link name="link_3">
      <pose>0.120000 0.000000 0.000000 0.000000 1.570790 0.000000</pose>
      <inertial>
        <pose>0 0 0 0 0 0</pose>
        <mass>0.0025000000000000001</mass>
        <inertia>
          <ixx>1e-03</ixx>
          <ixy>0</ixy>
          <ixz>0</ixz>
          <iyy>1e-03</iyy>
          <iyz>0</iyz>
          <izz>1e-03</izz>
        </inertia>
      </inertial>
      <collision name="link_3_collision">
        <pose>0 0 0 0 0 0</pose>
        <geometry>
          <cylinder>
            <length>0.048000000000000001</length>
            <radius>0.002</radius>
          </cylinder>
        </geometry>
        <surface>
          <friction>
            <torsional>
              <coefficient>0.05</coefficient>
            </torsional>
            <bullet>
              <friction>0.05</friction>
              <friction2>0.05</friction2>
            </bullet>
          </friction>
        </surface>
      </collision>
      <visual name="link_3_vis">
        <pose>0 0 0 0 0 0</pose>
        <geometry>
          <cylinder>
            <length>0.048000000000000001</length>
            <radius>0.002</radius>
          </cylinder>
        </geometry>
        <material>
          <diffuse>1 0.219999999 0 1</diffuse>
          <specular>0.5 0.5 0.5 1</specular>
          <pbr>
            <metal>
              <roughness>0.01</roughness>
              <metalness>0.01</metalness>
            </metal>
          </pbr>
        </material>
      </visual>
      <collision name="sphere_3_collision">
        <pose>0 0 0.024 0 0 0</pose>
        <geometry>
          <sphere>
            <radius>0.002</radius>
          </sphere>
        </geometry>
        <surface>
          <friction>
            <torsional>
              <coefficient>0.05</coefficient>
            </torsional>
            <bullet>
              <friction>0.05</friction>
              <friction2>0.05</friction2>
            </bullet>
          </friction>
        </surface>
      </collision>
      <visual name="sphere_3_vis">
        <pose>0 0 0.024 0 0 0</pose>
        <geometry>
          <sphere>
            <radius>0.002</radius>
          </sphere>
        </geometry>
        <material>
          <diffuse>1 0.219999999 0 1</diffuse>
          <specular>0.5 0.5 0.5 1</specular>
          <pbr>
            <metal>
              <roughness>0.01</roughness>
              <metalness>0.01</metalness>
            </metal>
          </pbr>
        </material>
      </visual>
      <enable_wind>false</enable_wind>
    </link>
    <link name="link_4">
      <pose>0.168000 0.000000 0.000000 0.000000 1.570790 0.000000</pose>
      <inertial>
        <pose>0 0 0 0 0 0</pose>
        <mass>0.0025000000000000001</mass>
        <inertia>
          <ixx>1e-03</ixx>
          <ixy>0</ixy>
          <ixz>0</ixz>
          <iyy>1e-03</iyy>
          <iyz>0</iyz>
          <izz>1e-03</izz>
        </inertia>
      </inertial>
      <collision name="link_4_collision">
        <pose>0 0 0 0 0 0</pose>
        <geometry>
          <cylinder>
            <length>0.048000000000000001</length>
            <radius>0.002</radius>
          </cylinder>
        </geometry>
        <surface>
          <friction>
            <torsional>
              <coefficient>0.05</coefficient>
            </torsional>
            <bullet>
              <friction>0.05</friction>
              <friction2>0.05</friction2>
            </bullet>
          </friction>
        </surface>
      </collision>
      <visual name="link_4_vis">
        <pose>0 0 0 0 0 0</pose>
        <geometry>
          <cylinder>
            <length>0.048000000000000001</length>
            <radius>0.002</radius>
          </cylinder>
        </geometry>
        <material>
          <diffuse>1 0.219999999 0 1</diffuse>
          <specular>0.5 0.5 0.5 1</specular>
          <pbr>
            <metal>
              <roughness>0.01</roughness>
              <metalness>0.01</metalness>
            </metal>
          </pbr>
        </material>
      </visual>
      <collision name="sphere_4_collision">
        <pose>0 0 0.024 0 0 0</pose>
        <geometry>
          <sphere>
            <radius>0.002</radius>
          </sphere>
        </geometry>
        <surface>
          <friction>
            <torsional>
              <coefficient>0.05</coefficient>
            </torsional>
            <bullet>
              <friction>0.05</friction>
              <friction2>0.05</friction2>
            </bullet>
          </friction>
        </surface>
      </collision>
      <visual name="sphere_4_vis">
        <pose>0 0 0.024 0 0 0</pose>
        <geometry>
          <sphere>
            <radius>0.002</radius>
          </sphere>
        </geometry>
        <material>
          <diffuse>1 0.219999999 0 1</diffuse>
          <specular>0.5 0.5 0.5 1</specular>
          <pbr>
            <metal>
              <roughness>0.01</roughness>
              <metalness>0.01</metalness>
            </metal>
          </pbr>
        </material>
      </visual>
      <enable_wind>false</enable_wind>
    </link>
    <link name="link_5">
      <pose>0.216000 0.000000 0.000000 0.000000 1.570790 0.000000</pose>
      <inertial>
        <pose>0 0 0 0 0 0</pose>
        <mass>0.0025000000000000001</mass>
        <inertia>
          <ixx>1e-03</ixx>
          <ixy>0</ixy>
          <ixz>0</ixz>
          <iyy>1e-03</iyy>
          <iyz>0</iyz>
          <izz>1e-03</izz>
        </inertia>
      </inertial>
      <collision name="link_5_collision">
        <pose>0 0 0 0 0 0</pose>
        <geometry>
          <cylinder>
            <length>0.048000000000000001</length>
            <radius>0.002</radius>
          </cylinder>
        </geometry>
        <surface>
          <friction>
            <torsional>
              <coefficient>0.05</coefficient>
            </torsional>
            <bullet>
              <friction>0.05</friction>
              <friction2>0.05</friction2>
            </bullet>
          </friction>
        </surface>
      </collision>
      <visual name="link_5_vis">
        <pose>0 0 0 0 0 0</pose>
        <geometry>
          <cylinder>
            <length>0.048000000000000001</length>
            <radius>0.002</radius>
          </cylinder>
        </geometry>
        <material>
          <diffuse>1 0.219999999 0 1</diffuse>
          <specular>0.5 0.5 0.5 1</specular>
          <pbr>
            <metal>
              <roughness>0.01</roughness>
              <metalness>0.01</metalness>
            </metal>
          </pbr>
        </material>
      </visual>
      <collision name="sphere_5_collision">
        <pose>0 0 0.024 0 0 0</pose>
        <geometry>
          <sphere>
            <radius>0.002</radius>
          </sphere>
        </geometry>
        <surface>
          <friction>
            <torsional>
              <coefficient>0.05</coefficient>
            </torsional>
            <bullet>
              <friction>0.05</friction>
              <friction2>0.05</friction2>
            </bullet>
          </friction>
        </surface>
      </collision>
      <visual name="sphere_5_vis">
        <pose>0 0 0.024 0 0 0</pose>
        <geometry>
          <sphere>
            <radius>0.002</radius>
          </sphere>
        </geometry>
        <material>
          <diffuse>1 0.219999999 0 1</diffuse>
          <specular>0.5 0.5 0.5 1</specular>
          <pbr>
            <metal>
              <roughness>0.01</roughness>
              <metalness>0.01</metalness>
            </metal>
          </pbr>
        </material>
      </visual>
      <enable_wind>false</enable_wind>
    </link>
    <link name="link_6">
      <pose>0.264000 0.000000 0.000000 0.000000 1.570790 0.000000</pose>
      <inertial>
        <pose>0 0 0 0 0 0</pose>
        <mass>0.0025000000000000001</mass>
        <inertia>
          <ixx>1e-03</ixx>
          <ixy>0</ixy>
          <ixz>0</ixz>
          <iyy>1e-03</iyy>
          <iyz>0</iyz>
          <izz>1e-03</izz>
        </inertia>
      </inertial>
      <collision name="link_6_collision">
        <pose>0 0 0 0 0 0</pose>
        <geometry>
          <cylinder>
            <length>0.048000000000000001</length>
            <radius>0.002</radius>
          </cylinder>
        </geometry>
      </collision>
      <visual name="link_6_vis">
        <pose>0 0 0 0 0 0</pose>
        <geometry>
          <cylinder>
            <length>0.048000000000000001</length>
            <radius>0.002</radius>
          </cylinder>
        </geometry>
        <material>
          <diffuse>1 0.219999999 0 1</diffuse>
          <specular>0.5 0.5 0.5 1</specular>
          <pbr>
            <metal>
              <roughness>0.01</roughness>
              <metalness>0.01</metalness>
            </metal>
          </pbr>
        </material>
      </visual>
      <collision name="sphere_6_collision">
        <pose>0 0 0.024 0 0 0</pose>
        <geometry>
          <sphere>
            <radius>0.002</radius>
          </sphere>
        </geometry>
        <surface>
          <friction>
            <torsional>
              <coefficient>0.05</coefficient>
            </torsional>
            <bullet>
              <friction>0.05</friction>
              <friction2>0.05</friction2>
            </bullet>
          </friction>
        </surface>
      </collision>
      <visual name="sphere_6_vis">
        <pose>0 0 0.024 0 0 0</pose>
        <geometry>
          <sphere>
            <radius>0.002</radius>
          </sphere>
        </geometry>
        <material>
          <diffuse>1 0.219999999 0 1</diffuse>
          <specular>0.5 0.5 0.5 1</specular>
          <pbr>
            <metal>
              <roughness>0.01</roughness>
              <metalness>0.01</metalness>
            </metal>
          </pbr>
        </material>
      </visual>
      <enable_wind>false</enable_wind>
    </link>
    <link name="link_7">
      <pose>0.312000 0.000000 0.000000 0.000000 1.570790 0.000000</pose>
      <inertial>
        <pose>0 0 0 0 0 0</pose>
        <mass>0.0025000000000000001</mass>
        <inertia>
          <ixx>1e-03</ixx>
          <ixy>0</ixy>
          <ixz>0</ixz>
          <iyy>1e-03</iyy>
          <iyz>0</iyz>
          <izz>1e-03</izz>
        </inertia>
      </inertial>
      <collision name="link_7_collision">
        <pose>0 0 0 0 0 0</pose>
        <geometry>
          <cylinder>
            <length>0.048000000000000001</length>
            <radius>0.002</radius>
          </cylinder>
        </geometry>
        <surface>
          <friction>
            <torsional>
              <coefficient>0.05</coefficient>
            </torsional>
            <bullet>
              <friction>0.05</friction>
              <friction2>0.05</friction2>
            </bullet>
          </friction>
        </surface>
      </collision>
      <visual name="link_7_vis">
        <pose>0 0 0 0 0 0</pose>
        <geometry>
          <cylinder>
            <length>0.048000000000000001</length>
            <radius>0.002</radius>
          </cylinder>
        </geometry>
        <material>
          <diffuse>1 0.219999999 0 1</diffuse>
          <specular>0.5 0.5 0.5 1</specular>
          <pbr>
            <metal>
              <roughness>0.01</roughness>
              <metalness>0.01</metalness>
            </metal>
          </pbr>
        </material>
      </visual>
      <collision name="sphere_7_collision">
        <pose>0 0 0.024 0 0 0</pose>
        <geometry>
          <sphere>
            <radius>0.002</radius>
          </sphere>
        </geometry>
        <surface>
          <friction>
            <torsional>
              <coefficient>0.05</coefficient>
            </torsional>
            <bullet>
              <friction>0.05</friction>
              <friction2>0.05</friction2>
            </bullet>
          </friction>
        </surface>
      </collision>
      <visual name="sphere_7_vis">
        <pose>0 0 0.024 0 0 0</pose>
        <geometry>
          <sphere>
            <radius>0.002</radius>
          </sphere>
        </geometry>
        <material>
          <diffuse>1 0.219999999 0 1</diffuse>
          <specular>0.5 0.5 0.5 1</specular>
          <pbr>
            <metal>
              <roughness>0.01</roughness>
              <metalness>0.01</metalness>
            </metal>
          </pbr>
        </material>
      </visual>
      <enable_wind>false</enable_wind>
    </link>
    <link name="link_8">
      <pose>0.360000 0.000000 0.000000 0.000000 1.570790 0.000000</pose>
      <inertial>
        <pose>0 0 0 0 0 0</pose>
        <mass>0.0025000000000000001</mass>
        <inertia>
          <ixx>1e-03</ixx>
          <ixy>0</ixy>
          <ixz>0</ixz>
          <iyy>1e-03</iyy>
          <iyz>0</iyz>
          <izz>1e-03</izz>
        </inertia>
      </inertial>
      <collision name="link_8_collision">
        <pose>0 0 0 0 0 0</pose>
        <geometry>
          <cylinder>
            <length>0.048000000000000001</length>
            <radius>0.002</radius>
          </cylinder>
        </geometry>
        <surface>
          <friction>
            <torsional>
              <coefficient>0.05</coefficient>
            </torsional>
            <bullet>
              <friction>0.05</friction>
              <friction2>0.05</friction2>
            </bullet>
          </friction>
        </surface>
      </collision>
      <visual name="link_8_vis">
        <pose>0 0 0 0 0 0</pose>
        <geometry>
          <cylinder>
            <length>0.048000000000000001</length>
            <radius>0.002</radius>
          </cylinder>
        </geometry>
        <material>
          <diffuse>1 0.219999999 0 1</diffuse>
          <specular>0.5 0.5 0.5 1</specular>
          <pbr>
            <metal>
              <roughness>0.01</roughness>
              <metalness>0.01</metalness>
            </metal>
          </pbr>
        </material>
      </visual>
      <collision name="sphere_8_collision">
        <pose>0 0 0.024 0 0 0</pose>
        <geometry>
          <sphere>
            <radius>0.002</radius>
          </sphere>
        </geometry>
        <surface>
          <friction>
            <torsional>
              <coefficient>0.05</coefficient>
            </torsional>
            <bullet>
              <friction>0.05</friction>
              <friction2>0.05</friction2>
            </bullet>
          </friction>
        </surface>
      </collision>
      <visual name="sphere_8_vis">
        <pose>0 0 0.024 0 0 0</pose>
        <geometry>
          <sphere>
            <radius>0.002</radius>
          </sphere>
        </geometry>
        <material>
          <diffuse>1 0.219999999 0 1</diffuse>
          <specular>0.5 0.5 0.5 1</specular>
          <pbr>
            <metal>
              <roughness>0.01</roughness>
              <metalness>0.01</metalness>
            </metal>
          </pbr>
        </material>
      </visual>
      <enable_wind>false</enable_wind>
    </link>
    <link name="link_9">
      <pose>0.408000 0.000000 0.000000 0.000000 1.570790 0.000000</pose>
      <inertial>
        <pose>0 0 0 0 0 0</pose>
        <mass>0.0025000000000000001</mass>
        <inertia>
          <ixx>1e-03</ixx>
          <ixy>0</ixy>
          <ixz>0</ixz>
          <iyy>1e-03</iyy>
          <iyz>0</iyz>
          <izz>1e-03</izz>
        </inertia>
      </inertial>
      <collision name="link_9_collision">
        <pose>0 0 0 0 0 0</pose>
        <geometry>
          <cylinder>
            <length>0.048000000000000001</length>
            <radius>0.002</radius>
          </cylinder>
        </geometry>
        <surface>
          <friction>
            <torsional>
              <coefficient>0.05</coefficient>
            </torsional>
            <bullet>
              <friction>0.05</friction>
              <friction2>0.05</friction2>
            </bullet>
          </friction>
        </surface>
      </collision>
      <visual name="link_9_vis">
        <pose>0 0 0 0 0 0</pose>
        <geometry>
          <cylinder>
            <length>0.048000000000000001</length>
            <radius>0.002</radius>
          </cylinder>
        </geometry>
        <material>
          <diffuse>1 0.219999999 0 1</diffuse>
          <specular>0.5 0.5 0.5 1</specular>
          <pbr>
            <metal>
              <roughness>0.01</roughness>
              <metalness>0.01</metalness>
            </metal>
          </pbr>
        </material>
      </visual>
      <collision name="sphere_9_collision">
        <pose>0 0 0.024 0 0 0</pose>
        <geometry>
          <sphere>
            <radius>0.002</radius>
          </sphere>
        </geometry>
        <surface>
          <friction>
            <torsional>
              <coefficient>0.05</coefficient>
            </torsional>
            <bullet>
              <friction>0.05</friction>
              <friction2>0.05</friction2>
            </bullet>
          </friction>
        </surface>
      </collision>
      <visual name="sphere_9_vis">
        <pose>0 0 0.024 0 0 0</pose>
        <geometry>
          <sphere>
            <radius>0.002</radius>
          </sphere>
        </geometry>
        <material>
          <diffuse>1 0.219999999 0 1</diffuse>
          <specular>0.5 0.5 0.5 1</specular>
          <pbr>
            <metal>
              <roughness>0.01</roughness>
              <metalness>0.01</metalness>
            </metal>
          </pbr>
        </material>
      </visual>
      <enable_wind>false</enable_wind>
    </link>
    <link name="link_10">
      <pose>0.456000 0.000000 0.000000 0.000000 1.570790 0.000000</pose>
      <inertial>
        <pose>0 0 0 0 0 0</pose>
        <mass>0.0025000000000000001</mass>
        <inertia>
          <ixx>1e-03</ixx>
          <ixy>0</ixy>
          <ixz>0</ixz>
          <iyy>1e-03</iyy>
          <iyz>0</iyz>
          <izz>1e-03</izz>
        </inertia>
      </inertial>
      <collision name="link_10_collision">
        <pose>0 0 0 0 0 0</pose>
        <geometry>
          <cylinder>
            <length>0.048000000000000001</length>
            <radius>0.002</radius>
          </cylinder>
        </geometry>
        <surface>
          <friction>
            <torsional>
              <coefficient>0.05</coefficient>
            </torsional>
            <bullet>
              <friction>0.05</friction>
              <friction2>0.05</friction2>
            </bullet>
          </friction>
        </surface>
      </collision>
      <visual name="link_10_vis">
        <pose>0 0 0 0 0 0</pose>
        <geometry>
          <cylinder>
            <length>0.048000000000000001</length>
            <radius>0.002</radius>
          </cylinder>
        </geometry>
        <material>
          <diffuse>1 0.219999999 0 1</diffuse>
          <specular>0.5 0.5 0.5 1</specular>
          <pbr>
            <metal>
              <roughness>0.01</roughness>
              <metalness>0.01</metalness>
            </metal>
          </pbr>
        </material>
      </visual>
      <collision name="sphere_10_collision">
        <pose>0 0 0.024 0 0 0</pose>
        <geometry>
          <sphere>
            <radius>0.002</radius>
          </sphere>
        </geometry>
        <surface>
          <friction>
            <torsional>
              <coefficient>0.05</coefficient>
            </torsional>
            <bullet>
              <friction>0.05</friction>
              <friction2>0.05</friction2>
            </bullet>
          </friction>
        </surface>
      </collision>
      <visual name="sphere_10_vis">
        <pose>0 0 0.024 0 0 0</pose>
        <geometry>
          <sphere>
            <radius>0.002</radius>
          </sphere>
        </geometry>
        <material>
          <diffuse>1 0.219999999 0 1</diffuse>
          <specular>0.5 0.5 0.5 1</specular>
          <pbr>
            <metal>
              <roughness>0.01</roughness>
              <metalness>0.01</metalness>
            </metal>
          </pbr>
        </material>
      </visual>
      <enable_wind>false</enable_wind>
    </link>
    <link name="link_11">
      <pose>0.504000 0.000000 0.000000 0.000000 1.570790 0.000000</pose>
      <inertial>
        <pose>0 0 0 0 0 0</pose>
        <mass>0.0025000000000000001</mass>
        <inertia>
          <ixx>1e-03</ixx>
          <ixy>0</ixy>
          <ixz>0</ixz>
          <iyy>1e-03</iyy>
          <iyz>0</iyz>
          <izz>1e-03</izz>
        </inertia>
      </inertial>
      <collision name="link_11_collision">
        <pose>0 0 0 0 0 0</pose>
        <geometry>
          <cylinder>
            <length>0.048000000000000001</length>
            <radius>0.002</radius>
          </cylinder>
        </geometry>
        <surface>
          <friction>
            <torsional>
              <coefficient>0.05</coefficient>
            </torsional>
            <bullet>
              <friction>0.05</friction>
              <friction2>0.05</friction2>
            </bullet>
          </friction>
        </surface>
      </collision>
      <visual name="link_11_vis">
        <pose>0 0 0 0 0 0</pose>
        <geometry>
          <cylinder>
            <length>0.048000000000000001</length>
            <radius>0.002</radius>
          </cylinder>
        </geometry>
        <material>
          <diffuse>1 0.219999999 0 1</diffuse>
          <specular>0.5 0.5 0.5 1</specular>
          <pbr>
            <metal>
              <roughness>0.01</roughness>
              <metalness>0.01</metalness>
            </metal>
          </pbr>
        </material>
      </visual>
      <collision name="sphere_11_collision">
        <pose>0 0 0.024 0 0 0</pose>
        <geometry>
          <sphere>
            <radius>0.002</radius>
          </sphere>
        </geometry>
        <surface>
          <friction>
            <torsional>
              <coefficient>0.05</coefficient>
            </torsional>
            <bullet>
              <friction>0.05</friction>
              <friction2>0.05</friction2>
            </bullet>
          </friction>
        </surface>
      </collision>
      <visual name="sphere_11_vis">
        <pose>0 0 0.024 0 0 0</pose>
        <geometry>
          <sphere>
            <radius>0.002</radius>
          </sphere>
        </geometry>
        <material>
          <diffuse>1 0.219999999 0 1</diffuse>
          <specular>0.5 0.5 0.5 1</specular>
          <pbr>
            <metal>
              <roughness>0.01</roughness>
              <metalness>0.01</metalness>
            </metal>
          </pbr>
        </material>
      </visual>
      <enable_wind>false</enable_wind>
    </link>
    <link name="link_12">
      <pose>0.552000 0.000000 0.000000 0.000000 1.570790 0.000000</pose>
      <inertial>
        <pose>0 0 0 0 0 0</pose>
        <mass>0.0025000000000000001</mass>
        <inertia>
          <ixx>1e-03</ixx>
          <ixy>0</ixy>
          <ixz>0</ixz>
          <iyy>1e-03</iyy>
          <iyz>0</iyz>
          <izz>1e-03</izz>
        </inertia>
      </inertial>
      <collision name="link_12_collision">
        <pose>0 0 0 0 0 0</pose>
        <geometry>
          <cylinder>
            <length>0.048000000000000001</length>
            <radius>0.002</radius>
          </cylinder>
        </geometry>
        <surface>
          <friction>
            <torsional>
              <coefficient>0.05</coefficient>
            </torsional>
            <bullet>
              <friction>0.05</friction>
              <friction2>0.05</friction2>
            </bullet>
          </friction>
        </surface>
      </collision>
      <visual name="link_12_vis">
        <pose>0 0 0 0 0 0</pose>
        <geometry>
          <cylinder>
            <length>0.048000000000000001</length>
            <radius>0.002</radius>
          </cylinder>
        </geometry>
        <material>
          <diffuse>1 0.219999999 0 1</diffuse>
          <specular>0.5 0.5 0.5 1</specular>
          <pbr>
            <metal>
              <roughness>0.01</roughness>
              <metalness>0.01</metalness>
            </metal>
          </pbr>
        </material>
      </visual>
      <collision name="sphere_12_collision">
        <pose>0 0 0.024 0 0 0</pose>
        <geometry>
          <sphere>
            <radius>0.002</radius>
          </sphere>
        </geometry>
        <surface>
          <friction>
            <torsional>
              <coefficient>0.05</coefficient>
            </torsional>
            <bullet>
              <friction>0.05</friction>
              <friction2>0.05</friction2>
            </bullet>
          </friction>
        </surface>
      </collision>
      <visual name="sphere_12_vis">
        <pose>0 0 0.024 0 0 0</pose>
        <geometry>
          <sphere>
            <radius>0.002</radius>
          </sphere>
        </geometry>
        <material>
          <diffuse>1 0.219999999 0 1</diffuse>
          <specular>0.5 0.5 0.5 1</specular>
          <pbr>
            <metal>
              <roughness>0.01</roughness>
              <metalness>0.01</metalness>
            </metal>
          </pbr>
        </material>
      </visual>
      <enable_wind>false</enable_wind>
    </link>
    <link name="link_13">
      <pose>0.600000 0.000000 0.000000 0.000000 1.570790 0.000000</pose>
      <inertial>
        <pose>0 0 0 0 0 0</pose>
        <mass>0.0025000000000000001</mass>
        <inertia>
          <ixx>1e-03</ixx>
          <ixy>0</ixy>
          <ixz>0</ixz>
          <iyy>1e-03</iyy>
          <iyz>0</iyz>
          <izz>1e-03</izz>
        </inertia>
      </inertial>
      <collision name="link_13_collision">
        <pose>0 0 0 0 0 0</pose>
        <geometry>
          <cylinder>
            <length>0.048000000000000001</length>
            <radius>0.002</radius>
          </cylinder>
        </geometry>
        <surface>
          <friction>
            <torsional>
              <coefficient>0.05</coefficient>
            </torsional>
            <bullet>
              <friction>0.05</friction>
              <friction2>0.05</friction2>
            </bullet>
          </friction>
        </surface>
      </collision>
      <visual name="link_13_vis">
        <pose>0 0 0 0 0 0</pose>
        <geometry>
          <cylinder>
            <length>0.048000000000000001</length>
            <radius>0.002</radius>
          </cylinder>
        </geometry>
        <material>
          <diffuse>1 0.219999999 0 1</diffuse>
          <specular>0.5 0.5 0.5 1</specular>
          <pbr>
            <metal>
              <roughness>0.01</roughness>
              <metalness>0.01</metalness>
            </metal>
          </pbr>
        </material>
      </visual>
      <collision name="sphere_13_collision">
        <pose>0 0 0.024 0 0 0</pose>
        <geometry>
          <sphere>
            <radius>0.002</radius>
          </sphere>
        </geometry>
        <surface>
          <friction>
            <torsional>
              <coefficient>0.05</coefficient>
            </torsional>
            <bullet>
              <friction>0.05</friction>
              <friction2>0.05</friction2>
            </bullet>
          </friction>
        </surface>
      </collision>
      <visual name="sphere_13_vis">
        <pose>0 0 0.024 0 0 0</pose>
        <geometry>
          <sphere>
            <radius>0.002</radius>
          </sphere>
        </geometry>
        <material>
          <diffuse>1 0.219999999 0 1</diffuse>
          <specular>0.5 0.5 0.5 1</specular>
          <pbr>
            <metal>
              <roughness>0.01</roughness>
              <metalness>0.01</metalness>
            </metal>
          </pbr>
        </material>
      </visual>
      <enable_wind>false</enable_wind>
    </link>
    <link name="link_14">
      <pose>0.648000 0.000000 0.000000 0.000000 1.570790 0.000000</pose>
      <inertial>
        <pose>0 0 0 0 0 0</pose>
        <mass>0.0025000000000000001</mass>
        <inertia>
          <ixx>1e-03</ixx>
          <ixy>0</ixy>
          <ixz>0</ixz>
          <iyy>1e-03</iyy>
          <iyz>0</iyz>
          <izz>1e-03</izz>
        </inertia>
      </inertial>
      <collision name="link_14_collision">
        <pose>0 0 0 0 0 0</pose>
        <geometry>
          <cylinder>
            <length>0.048000000000000001</length>
            <radius>0.002</radius>
          </cylinder>
        </geometry>
        <surface>
          <friction>
            <torsional>
              <coefficient>0.05</coefficient>
            </torsional>
            <bullet>
              <friction>0.05</friction>
              <friction2>0.05</friction2>
            </bullet>
          </friction>
        </surface>
      </collision>
      <visual name="link_14_vis">
        <pose>0 0 0 0 0 0</pose>
        <geometry>
          <cylinder>
            <length>0.048000000000000001</length>
            <radius>0.002</radius>
          </cylinder>
        </geometry>
        <material>
          <diffuse>1 0.219999999 0 1</diffuse>
          <specular>0.5 0.5 0.5 1</specular>
          <pbr>
            <metal>
              <roughness>0.01</roughness>
              <metalness>0.01</metalness>
            </metal>
          </pbr>
        </material>
      </visual>
      <collision name="sphere_14_collision">
        <pose>0 0 0.024 0 0 0</pose>
        <geometry>
          <sphere>
            <radius>0.002</radius>
          </sphere>
        </geometry>
        <surface>
          <friction>
            <torsional>
              <coefficient>0.05</coefficient>
            </torsional>
            <bullet>
              <friction>0.05</friction>
              <friction2>0.05</friction2>
            </bullet>
          </friction>
        </surface>
      </collision>
      <visual name="sphere_14_vis">
        <pose>0 0 0.024 0 0 0</pose>
        <geometry>
          <sphere>
            <radius>0.002</radius>
          </sphere>
        </geometry>
        <material>
          <diffuse>1 0.219999999 0 1</diffuse>
          <specular>0.5 0.5 0.5 1</specular>
          <pbr>
            <metal>
              <roughness>0.01</roughness>
              <metalness>0.01</metalness>
            </metal>
          </pbr>
        </material>
      </visual>
      <enable_wind>false</enable_wind>
    </link>
    <link name="link_15">
      <pose>0.696000 0.000000 0.000000 0.000000 1.570790 0.000000</pose>
      <inertial>
        <pose>0 0 0 0 0 0</pose>
        <mass>0.0025000000000000001</mass>
        <inertia>
          <ixx>1e-03</ixx>
          <ixy>0</ixy>
          <ixz>0</ixz>
          <iyy>1e-03</iyy>
          <iyz>0</iyz>
          <izz>1e-03</izz>
        </inertia>
      </inertial>
      <collision name="link_15_collision">
        <pose>0 0 0 0 0 0</pose>
        <geometry>
          <cylinder>
            <length>0.048000000000000001</length>
            <radius>0.002</radius>
          </cylinder>
        </geometry>
        <surface>
          <friction>
            <torsional>
              <coefficient>0.05</coefficient>
            </torsional>
            <bullet>
              <friction>0.05</friction>
              <friction2>0.05</friction2>
            </bullet>
          </friction>
        </surface>
      </collision>
      <visual name="link_15_vis">
        <pose>0 0 0 0 0 0</pose>
        <geometry>
          <cylinder>
            <length>0.048000000000000001</length>
            <radius>0.002</radius>
          </cylinder>
        </geometry>
        <material>
          <diffuse>1 0.219999999 0 1</diffuse>
          <specular>0.5 0.5 0.5 1</specular>
          <pbr>
            <metal>
              <roughness>0.01</roughness>
              <metalness>0.01</metalness>
            </metal>
          </pbr>
        </material>
      </visual>
      <collision name="sphere_15_collision">
        <pose>0 0 0.024 0 0 0</pose>
        <geometry>
          <sphere>
            <radius>0.002</radius>
          </sphere>
        </geometry>
        <surface>
          <friction>
            <torsional>
              <coefficient>0.05</coefficient>
            </torsional>
            <bullet>
              <friction>0.05</friction>
              <friction2>0.05</friction2>
            </bullet>
          </friction>
        </surface>
      </collision>
      <visual name="sphere_15_vis">
        <pose>0 0 0.024 0 0 0</pose>
        <geometry>
          <sphere>
            <radius>0.002</radius>
          </sphere>
        </geometry>
        <material>
          <diffuse>1 0.219999999 0 1</diffuse>
          <specular>0.5 0.5 0.5 1</specular>
          <pbr>
            <metal>
              <roughness>0.01</roughness>
              <metalness>0.01</metalness>
            </metal>
          </pbr>
        </material>
      </visual>
      <enable_wind>false</enable_wind>
    </link>
    <link name="link_16">
      <pose>0.744000 0.000000 0.000000 0.000000 1.570790 0.000000</pose>
      <inertial>
        <pose>0 0 0 0 0 0</pose>
        <mass>0.0025000000000000001</mass>
        <inertia>
          <ixx>1e-03</ixx>
          <ixy>0</ixy>
          <ixz>0</ixz>
          <iyy>1e-03</iyy>
          <iyz>0</iyz>
          <izz>1e-03</izz>
        </inertia>
      </inertial>
      <collision name="link_16_collision">
        <pose>0 0 0 0 0 0</pose>
        <geometry>
          <cylinder>
            <length>0.048000000000000001</length>
            <radius>0.002</radius>
          </cylinder>
        </geometry>
        <surface>
          <friction>
            <torsional>
              <coefficient>0.05</coefficient>
            </torsional>
            <bullet>
              <friction>0.05</friction>
              <friction2>0.05</friction2>
            </bullet>
          </friction>
        </surface>
      </collision>
      <visual name="link_16_vis">
        <pose>0 0 0 0 0 0</pose>
        <geometry>
          <cylinder>
            <length>0.048000000000000001</length>
            <radius>0.002</radius>
          </cylinder>
        </geometry>
        <material>
          <diffuse>1 0.219999999 0 1</diffuse>
          <specular>0.5 0.5 0.5 1</specular>
          <pbr>
            <metal>
              <roughness>0.01</roughness>
              <metalness>0.01</metalness>
            </metal>
          </pbr>
        </material>
      </visual>
      <collision name="sphere_16_collision">
        <pose>0 0 0.024 0 0 0</pose>
        <geometry>
          <sphere>
            <radius>0.002</radius>
          </sphere>
        </geometry>
        <surface>
          <friction>
            <torsional>
              <coefficient>0.05</coefficient>
            </torsional>
            <bullet>
              <friction>0.05</friction>
              <friction2>0.05</friction2>
            </bullet>
          </friction>
        </surface>
      </collision>
      <visual name="sphere_16_vis">
        <pose>0 0 0.024 0 0 0</pose>
        <geometry>
          <sphere>
            <radius>0.002</radius>
          </sphere>
        </geometry>
        <material>
          <diffuse>1 0.219999999 0 1</diffuse>
          <specular>0.5 0.5 0.5 1</specular>
          <pbr>
            <metal>
              <roughness>0.01</roughness>
              <metalness>0.01</metalness>
            </metal>
          </pbr>
        </material>
      </visual>
      <enable_wind>false</enable_wind>
    </link>
    <link name="link_17">
      <pose>0.792000 0.000000 0.000000 0.000000 1.570790 0.000000</pose>
      <inertial>
        <pose>0 0 0 0 0 0</pose>
        <mass>0.0025000000000000001</mass>
        <inertia>
          <ixx>1e-03</ixx>
          <ixy>0</ixy>
          <ixz>0</ixz>
          <iyy>1e-03</iyy>
          <iyz>0</iyz>
          <izz>1e-03</izz>
        </inertia>
      </inertial>
      <collision name="link_17_collision">
        <pose>0 0 0 0 0 0</pose>
        <geometry>
          <cylinder>
            <length>0.048000000000000001</length>
            <radius>0.002</radius>
          </cylinder>
        </geometry>
        <surface>
          <friction>
            <torsional>
              <coefficient>0.05</coefficient>
            </torsional>
            <bullet>
              <friction>0.05</friction>
              <friction2>0.05</friction2>
            </bullet>
          </friction>
        </surface>
      </collision>
      <visual name="link_17_vis">
        <pose>0 0 0 0 0 0</pose>
        <geometry>
          <cylinder>
            <length>0.048000000000000001</length>
            <radius>0.002</radius>
          </cylinder>
        </geometry>
        <material>
          <diffuse>1 0.219999999 0 1</diffuse>
          <specular>0.5 0.5 0.5 1</specular>
          <pbr>
            <metal>
              <roughness>0.01</roughness>
              <metalness>0.01</metalness>
            </metal>
          </pbr>
        </material>
      </visual>
      <collision name="sphere_17_collision">
        <pose>0 0 0.024 0 0 0</pose>
        <geometry>
          <sphere>
            <radius>0.002</radius>
          </sphere>
        </geometry>
        <surface>
          <friction>
            <torsional>
              <coefficient>0.05</coefficient>
            </torsional>
            <bullet>
              <friction>0.05</friction>
              <friction2>0.05</friction2>
            </bullet>
          </friction>
        </surface>
      </collision>
      <visual name="sphere_17_vis">
        <pose>0 0 0.024 0 0 0</pose>
        <geometry>
          <sphere>
            <radius>0.002</radius>
          </sphere>
        </geometry>
        <material>
          <diffuse>1 0.219999999 0 1</diffuse>
          <specular>0.5 0.5 0.5 1</specular>
          <pbr>
            <metal>
              <roughness>0.01</roughness>
              <metalness>0.01</metalness>
            </metal>
          </pbr>
        </material>
      </visual>
      <enable_wind>false</enable_wind>
    </link>
    <link name="link_18">
      <pose>0.840000 0.000000 0.000000 0.000000 1.570790 0.000000</pose>
      <inertial>
        <pose>0 0 0 0 0 0</pose>
        <mass>0.0025000000000000001</mass>
        <inertia>
          <ixx>1e-03</ixx>
          <ixy>0</ixy>
          <ixz>0</ixz>
          <iyy>1e-03</iyy>
          <iyz>0</iyz>
          <izz>1e-03</izz>
        </inertia>
      </inertial>
      <collision name="link_18_collision">
        <pose>0 0 0 0 0 0</pose>
        <geometry>
          <cylinder>
            <length>0.048000000000000001</length>
            <radius>0.002</radius>
          </cylinder>
        </geometry>
        <surface>
          <friction>
            <torsional>
              <coefficient>0.05</coefficient>
            </torsional>
            <bullet>
              <friction>0.05</friction>
              <friction2>0.05</friction2>
            </bullet>
          </friction>
        </surface>
      </collision>
      <visual name="link_18_vis">
        <pose>0 0 0 0 0 0</pose>
        <geometry>
          <cylinder>
            <length>0.048000000000000001</length>
            <radius>0.002</radius>
          </cylinder>
        </geometry>
        <material>
          <diffuse>1 0.219999999 0 1</diffuse>
          <specular>0.5 0.5 0.5 1</specular>
          <pbr>
            <metal>
              <roughness>0.01</roughness>
              <metalness>0.01</metalness>
            </metal>
          </pbr>
        </material>
      </visual>
      <collision name="sphere_18_collision">
        <pose>0 0 0.024 0 0 0</pose>
        <geometry>
          <sphere>
            <radius>0.002</radius>
          </sphere>
        </geometry>
        <surface>
          <friction>
            <torsional>
              <coefficient>0.05</coefficient>
            </torsional>
            <bullet>
              <friction>0.05</friction>
              <friction2>0.05</friction2>
            </bullet>
          </friction>
        </surface>
      </collision>
      <visual name="sphere_18_vis">
        <pose>0 0 0.024 0 0 0</pose>
        <geometry>
          <sphere>
            <radius>0.002</radius>
          </sphere>
        </geometry>
        <material>
          <diffuse>1 0.219999999 0 1</diffuse>
          <specular>0.5 0.5 0.5 1</specular>
          <pbr>
            <metal>
              <roughness>0.01</roughness>
              <metalness>0.01</metalness>
            </metal>
          </pbr>
        </material>
      </visual>
      <enable_wind>false</enable_wind>
    </link>
    <link name="link_19">
      <pose>0.888000 0.000000 0.000000 0.000000 1.570790 0.000000</pose>
      <inertial>
        <pose>0 0 0 0 0 0</pose>
        <mass>0.0025000000000000001</mass>
        <inertia>
          <ixx>1e-03</ixx>
          <ixy>0</ixy>
          <ixz>0</ixz>
          <iyy>1e-03</iyy>
          <iyz>0</iyz>
          <izz>1e-03</izz>
        </inertia>
      </inertial>
      <collision name="link_19_collision">
        <pose>0 0 0 0 0 0</pose>
        <geometry>
          <cylinder>
            <length>0.048000000000000001</length>
            <radius>0.002</radius>
          </cylinder>
        </geometry>
        <surface>
          <friction>
            <torsional>
              <coefficient>0.05</coefficient>
            </torsional>
            <bullet>
              <friction>0.05</friction>
              <friction2>0.05</friction2>
            </bullet>
          </friction>
        </surface>
      </collision>
      <visual name="link_19_vis">
        <pose>0 0 0 0 0 0</pose>
        <geometry>
          <cylinder>
            <length>0.048000000000000001</length>
            <radius>0.002</radius>
          </cylinder>
        </geometry>
        <material>
          <diffuse>1 0.219999999 0 1</diffuse>
          <specular>0.5 0.5 0.5 1</specular>
          <pbr>
            <metal>
              <roughness>0.01</roughness>
              <metalness>0.01</metalness>
            </metal>
          </pbr>
        </material>
      </visual>
      <collision name="sphere_19_collision">
        <pose>0 0 0.024 0 0 0</pose>
        <geometry>
          <sphere>
            <radius>0.002</radius>
          </sphere>
        </geometry>
        <surface>
          <friction>
            <torsional>
              <coefficient>0.05</coefficient>
            </torsional>
            <bullet>
              <friction>0.05</friction>
              <friction2>0.05</friction2>
            </bullet>
          </friction>
        </surface>
      </collision>
      <visual name="sphere_19_vis">
        <pose>0 0 0.024 0 0 0</pose>
        <geometry>
          <sphere>
            <radius>0.002</radius>
          </sphere>
        </geometry>
        <material>
          <diffuse>1 0.219999999 0 1</diffuse>
          <specular>0.5 0.5 0.5 1</specular>
          <pbr>
            <metal>
              <roughness>0.01</roughness>
              <metalness>0.01</metalness>
            </metal>
          </pbr>
        </material>
      </visual>
      <enable_wind>false</enable_wind>
    </link>
    <link name="link_20">
      <pose>0.936000 0.000000 0.000000 0.000000 1.570790 0.000000</pose>
      <inertial>
        <pose>0 0 0 0 0 0</pose>
        <mass>0.0025000000000000001</mass>
        <inertia>
          <ixx>1e-03</ixx>
          <ixy>0</ixy>
          <ixz>0</ixz>
          <iyy>1e-03</iyy>
          <iyz>0</iyz>
          <izz>1e-03</izz>
        </inertia>
      </inertial>
      <collision name="link_20_collision">
        <pose>0 0 0 0 0 0</pose>
        <geometry>
          <cylinder>
            <length>0.048000000000000001</length>
            <radius>0.002</radius>
          </cylinder>
        </geometry>
        <surface>
          <friction>
            <torsional>
              <coefficient>0.05</coefficient>
            </torsional>
            <bullet>
              <friction>0.05</friction>
              <friction2>0.05</friction2>
            </bullet>
          </friction>
        </surface>
      </collision>
      <visual name="link_20_vis">
        <pose>0 0 0 0 0 0</pose>
        <geometry>
          <cylinder>
            <length>0.048000000000000001</length>
            <radius>0.002</radius>
          </cylinder>
        </geometry>
        <material>
          <diffuse>1 0.219999999 0 1</diffuse>
          <specular>0.5 0.5 0.5 1</specular>
          <pbr>
            <metal>
              <roughness>0.01</roughness>
              <metalness>0.01</metalness>
            </metal>
          </pbr>
        </material>
      </visual>
      <collision name="sphere_20_collision">
        <pose>0 0 0.024 0 0 0</pose>
        <geometry>
          <sphere>
            <radius>0.002</radius>
          </sphere>
        </geometry>
        <surface>
          <friction>
            <torsional>
              <coefficient>0.05</coefficient>
            </torsional>
            <bullet>
              <friction>0.05</friction>
              <friction2>0.05</friction2>
            </bullet>
          </friction>
        </surface>
      </collision>
      <visual name="sphere_20_vis">
        <pose>0 0 0.024 0 0 0</pose>
        <geometry>
          <sphere>
            <radius>0.002</radius>
          </sphere>
        </geometry>
        <material>
          <diffuse>1 0.219999999 0 1</diffuse>
          <specular>0.5 0.5 0.5 1</specular>
          <pbr>
            <metal>
              <roughness>0.01</roughness>
              <metalness>0.01</metalness>
            </metal>
          </pbr>
        </material>
      </visual>
      <enable_wind>false</enable_wind>
    </link>
    <joint name="joint_1" type="ball">
      <pose>0.000000 0.000000 -0.024000 0.000000 0.000000 0.000000</pose>
      <parent>link_1</parent>
      <child>link_2</child>
      <axis>
        <xyz>-2.5568197732639408e-16 -6.9388939039072308e-17 1</xyz>
        <limit>
          <lower>-inf</lower>
          <upper>inf</upper>
          <effort>inf</effort>
          <velocity>inf</velocity>
          <stiffness>100000000</stiffness>
          <dissipation>1</dissipation>
        </limit>
        <dynamics>
          <spring_reference>0</spring_reference>
          <spring_stiffness>0</spring_stiffness>
          <damping>0.2</damping>
          <friction>0</friction>
        </dynamics>
      </axis>
    </joint>
    <joint name="joint_2" type="ball">
      <pose>0.000000 0.000000 -0.024000 0.000000 0.000000 0.000000</pose>
      <parent>link_2</parent>
      <child>link_3</child>
      <axis>
        <xyz>-4.336808689942141e-19 7.63278329429795e-17 1</xyz>
        <limit>
          <lower>-inf</lower>
          <upper>inf</upper>
          <effort>inf</effort>
          <velocity>inf</velocity>
          <stiffness>100000000</stiffness>
          <dissipation>1</dissipation>
        </limit>
        <dynamics>
          <spring_reference>0</spring_reference>
          <spring_stiffness>0</spring_stiffness>
          <damping>0.2</damping>
          <friction>0</friction>
        </dynamics>
      </axis>
    </joint>
    <joint name="joint_3" type="ball">
      <pose>0.000000 0.000000 -0.024000 0.000000 0.000000 0.000000</pose>
      <parent>link_3</parent>
      <child>link_4</child>
      <axis>
        <xyz>-1.1102230246251565e-16 1.1102230246251564e-16 1</xyz>
        <limit>
          <lower>-inf</lower>
          <upper>inf</upper>
          <effort>inf</effort>
          <velocity>inf</velocity>
          <stiffness>100000000</stiffness>
          <dissipation>1</dissipation>
        </limit>
        <dynamics>
          <spring_reference>0</spring_reference>
          <spring_stiffness>0</spring_stiffness>
          <damping>0.2</damping>
          <friction>0</friction>
        </dynamics>
      </axis>
    </joint>
    <joint name="joint_4" type="ball">
      <pose>0.000000 0.000000 -0.024000 0.000000 0.000000 0.000000</pose>
      <parent>link_4</parent>
      <child>link_5</child>
      <axis>
        <xyz>1.3183898417423731e-16 5.5511151231257839e-17 1</xyz>
        <limit>
          <lower>-inf</lower>
          <upper>inf</upper>
          <effort>inf</effort>
          <velocity>inf</velocity>
          <stiffness>100000000</stiffness>
          <dissipation>1</dissipation>
        </limit>
        <dynamics>
          <spring_reference>0</spring_reference>
          <spring_stiffness>0</spring_stiffness>
          <damping>0.2</damping>
          <friction>0</friction>
        </dynamics>
      </axis>
    </joint>
    <joint name="joint_5" type="ball">
      <pose>0.000000 0.000000 -0.024000 0.000000 0.000000 0.000000</pose>
      <parent>link_5</parent>
      <child>link_6</child>
      <axis>
        <xyz>-2.0816681711721636e-17 1.1102230246251565e-16 1</xyz>
        <limit>
          <lower>-inf</lower>
          <upper>inf</upper>
          <effort>inf</effort>
          <velocity>inf</velocity>
          <stiffness>100000000</stiffness>
          <dissipation>1</dissipation>
        </limit>
        <dynamics>
          <spring_reference>0</spring_reference>
          <spring_stiffness>0</spring_stiffness>
          <damping>0.2</damping>
          <friction>0</friction>
        </dynamics>
      </axis>
    </joint>
    <joint name="joint_6" type="ball">
      <pose>0.000000 0.000000 -0.024000 0.000000 0.000000 0.000000</pose>
      <parent>link_6</parent>
      <child>link_7</child>
      <axis>
        <xyz>-5.8980598183211417e-17 1.3877787807814417e-17 1</xyz>
        <limit>
          <lower>-inf</lower>
          <upper>inf</upper>
          <effort>inf</effort>
          <velocity>inf</velocity>
          <stiffness>100000000</stiffness>
          <dissipation>1</dissipation>
        </limit>
        <dynamics>
          <spring_reference>0</spring_reference>
          <spring_stiffness>0</spring_stiffness>
          <damping>0.2</damping>
          <friction>0</friction>
        </dynamics>
      </axis>
    </joint>
    <joint name="joint_7" type="ball">
      <pose>0.000000 0.000000 -0.024000 0.000000 0.000000 0.000000</pose>
      <parent>link_7</parent>
      <child>link_8</child>
      <axis>
        <xyz>2.2985086056692689e-16 1.960237527853792e-16 1</xyz>
        <limit>
          <lower>-inf</lower>
          <upper>inf</upper>
          <effort>inf</effort>
          <velocity>inf</velocity>
          <stiffness>100000000</stiffness>
          <dissipation>1</dissipation>
        </limit>
        <dynamics>
          <spring_reference>0</spring_reference>
          <spring_stiffness>0</spring_stiffness>
          <damping>0.2</damping>
          <friction>0</friction>
        </dynamics>
      </axis>
    </joint>
    <joint name="joint_8" type="ball">
      <pose>0.000000 0.000000 -0.024000 0.000000 0.000000 0.000000</pose>
      <parent>link_8</parent>
      <child>link_9</child>
      <axis>
        <xyz>-1.5742615544489524e-16 4.163336342344337e-17 1</xyz>
        <limit>
          <lower>-inf</lower>
          <upper>inf</upper>
          <effort>inf</effort>
          <velocity>inf</velocity>
          <stiffness>100000000</stiffness>
          <dissipation>1</dissipation>
        </limit>
        <dynamics>
          <spring_reference>0</spring_reference>
          <spring_stiffness>0</spring_stiffness>
          <damping>0.2</damping>
          <friction>0</friction>
        </dynamics>
      </axis>
    </joint>
    <joint name="joint_9" type="ball">
      <pose>0.000000 0.000000 -0.024000 0.000000 0.000000 0.000000</pose>
      <parent>link_9</parent>
      <child>link_10</child>
      <axis>
        <xyz>-7.2858385991025898e-17 -1.0408340855860843e-16 1</xyz>
        <limit>
          <lower>-inf</lower>
          <upper>inf</upper>
          <effort>inf</effort>
          <velocity>inf</velocity>
          <stiffness>100000000</stiffness>
          <dissipation>1</dissipation>
        </limit>
        <dynamics>
          <spring_reference>0</spring_reference>
          <spring_stiffness>0</spring_stiffness>
          <damping>0.2</damping>
          <friction>0</friction>
        </dynamics>
      </axis>
    </joint>
    <joint name="joint_10" type="ball">
      <pose>0.000000 0.000000 -0.024000 0.000000 0.000000 0.000000</pose>
      <parent>link_10</parent>
      <child>link_11</child>
      <axis>
        <xyz>-4.5102810375397028e-17 -8.3266726846886716e-17 1</xyz>
        <limit>
          <lower>-inf</lower>
          <upper>inf</upper>
          <effort>inf</effort>
          <velocity>inf</velocity>
          <stiffness>100000000</stiffness>
          <dissipation>1</dissipation>
        </limit>
        <dynamics>
          <spring_reference>0</spring_reference>
          <spring_stiffness>0</spring_stiffness>
          <damping>0.2</damping>
          <friction>0</friction>
        </dynamics>
      </axis>
    </joint>
    <joint name="joint_11" type="ball">
      <pose>0.000000 0.000000 -0.024000 0.000000 0.000000 0.000000</pose>
      <parent>link_11</parent>
      <child>link_12</child>
      <axis>
        <xyz>-1.3877787807814457e-17 5.5511151231257827e-17 1</xyz>
        <limit>
          <lower>-inf</lower>
          <upper>inf</upper>
          <effort>inf</effort>
          <velocity>inf</velocity>
          <stiffness>100000000</stiffness>
          <dissipation>1</dissipation>
        </limit>
        <dynamics>
          <spring_reference>0</spring_reference>
          <spring_stiffness>0</spring_stiffness>
          <damping>0.2</damping>
          <friction>0</friction>
        </dynamics>
      </axis>
    </joint>
    <joint name="joint_12" type="ball">
      <pose>0.000000 0.000000 -0.024000 0.000000 0.000000 0.000000</pose>
      <parent>link_12</parent>
      <child>link_13</child>
      <axis>
        <xyz>4.8572257327350599e-16 3.8163916471489565e-17 1</xyz>
        <limit>
          <lower>-inf</lower>
          <upper>inf</upper>
          <effort>inf</effort>
          <velocity>inf</velocity>
          <stiffness>100000000</stiffness>
          <dissipation>1</dissipation>
        </limit>
        <dynamics>
          <spring_reference>0</spring_reference>
          <spring_stiffness>0</spring_stiffness>
          <damping>0.2</damping>
          <friction>0</friction>
        </dynamics>
      </axis>
    </joint>
    <joint name="joint_13" type="ball">
      <pose>0.000000 0.000000 -0.024000 0.000000 0.000000 0.000000</pose>
      <parent>link_13</parent>
      <child>link_14</child>
      <axis>
        <xyz>4.1633363423443346e-17 -5.5511151231257815e-17 1</xyz>
        <limit>
          <lower>-inf</lower>
          <upper>inf</upper>
          <effort>inf</effort>
          <velocity>inf</velocity>
          <stiffness>100000000</stiffness>
          <dissipation>1</dissipation>
        </limit>
        <dynamics>
          <spring_reference>0</spring_reference>
          <spring_stiffness>0</spring_stiffness>
          <damping>0.2</damping>
          <friction>0</friction>
        </dynamics>
      </axis>
    </joint>
    <joint name="joint_14" type="ball">
      <pose>0.000000 0.000000 -0.024000 0.000000 0.000000 0.000000</pose>
      <parent>link_14</parent>
      <child>link_15</child>
      <axis>
        <xyz>5.5511151231257815e-17 7.6327832942979512e-17 1</xyz>
        <limit>
          <lower>-inf</lower>
          <upper>inf</upper>
          <effort>inf</effort>
          <velocity>inf</velocity>
          <stiffness>100000000</stiffness>
          <dissipation>1</dissipation>
        </limit>
        <dynamics>
          <spring_reference>0</spring_reference>
          <spring_stiffness>0</spring_stiffness>
          <damping>0.2</damping>
          <friction>0</friction>
        </dynamics>
      </axis>
    </joint>
    <joint name="joint_15" type="ball">
      <pose>0.000000 0.000000 -0.024000 0.000000 0.000000 0.000000</pose>
      <parent>link_15</parent>
      <child>link_16</child>
      <axis>
        <xyz>5.2041704279304207e-17 -8.3266726846886728e-17 1</xyz>
        <limit>
          <lower>-inf</lower>
          <upper>inf</upper>
          <effort>inf</effort>
          <velocity>inf</velocity>
          <stiffness>100000000</stiffness>
          <dissipation>1</dissipation>
        </limit>
        <dynamics>
          <spring_reference>0</spring_reference>
          <spring_stiffness>0</spring_stiffness>
          <damping>0.2</damping>
          <friction>0</friction>
        </dynamics>
      </axis>
    </joint>
    <joint name="joint_16" type="ball">
      <pose>0.000000 0.000000 -0.024000 0.000000 0.000000 0.000000</pose>
      <parent>link_16</parent>
      <child>link_17</child>
      <axis>
        <xyz>1.3877787807814444e-17 -2.7755575615628907e-17 1</xyz>
        <limit>
          <lower>-inf</lower>
          <upper>inf</upper>
          <effort>inf</effort>
          <velocity>inf</velocity>
          <stiffness>100000000</stiffness>
          <dissipation>1</dissipation>
        </limit>
        <dynamics>
          <spring_reference>0</spring_reference>
          <spring_stiffness>0</spring_stiffness>
          <damping>0.2</damping>
          <friction>0</friction>
        </dynamics>
      </axis>
    </joint>
    <joint name="joint_17" type="ball">
      <pose>0.000000 0.000000 -0.024000 0.000000 0.000000 0.000000</pose>
      <parent>link_17</parent>
      <child>link_18</child>
      <axis>
        <xyz>1.6653345369377343e-16 -2.7755575615628926e-17 1</xyz>
        <limit>
          <lower>-inf</lower>
          <upper>inf</upper>
          <effort>inf</effort>
          <velocity>inf</velocity>
          <stiffness>100000000</stiffness>
          <dissipation>1</dissipation>
        </limit>
        <dynamics>
          <spring_reference>0</spring_reference>
          <spring_stiffness>0</spring_stiffness>
          <damping>0.2</damping>
          <friction>0</friction>
        </dynamics>
      </axis>
    </joint>
    <joint name="joint_18" type="ball">
      <pose>0.000000 0.000000 -0.024000 0.000000 0.000000 0.000000</pose>
      <parent>link_18</parent>
      <child>link_19</child>
      <axis>
        <xyz>3.3306690738754696e-16 -1.474514954580286e-17 1</xyz>
        <limit>
          <lower>-inf</lower>
          <upper>inf</upper>
          <effort>inf</effort>
          <velocity>inf</velocity>
          <stiffness>100000000</stiffness>
          <dissipation>1</dissipation>
        </limit>
        <dynamics>
          <spring_reference>0</spring_reference>
          <spring_stiffness>0</spring_stiffness>
          <damping>0.2</damping>
          <friction>0</friction>
        </dynamics>
      </axis>
    </joint>
    <joint name="joint_19" type="ball">
      <pose>0.000000 0.000000 -0.024000 0.000000 0.000000 0.000000</pose>
      <parent>link_19</parent>
      <child>link_20</child>
      <axis>
        <xyz>1.8735013540549517e-16 2.7755575615628914e-16 1</xyz>
        <limit>
          <lower>-inf</lower>
          <upper>inf</upper>
          <effort>inf</effort>
          <velocity>inf</velocity>
          <stiffness>100000000</stiffness>
          <dissipation>1</dissipation>
        </limit>
        <dynamics>
          <spring_reference>0</spring_reference>
          <spring_stiffness>0</spring_stiffness>
          <damping>0.2</damping>
          <friction>0</friction>
        </dynamics>
      </axis>
    </joint>
    <link name="cable_connection_0">
      <inertial>
        <pose>0 0 0 0 0 0</pose>
        <mass>0.01</mass>
        <inertia>
          <ixx>0.01</ixx>
          <ixy>0</ixy>
          <ixz>0</ixz>
          <iyy>0.01</iyy>
          <iyz>0</iyz>
          <izz>0.01</izz>
        </inertia>
      </inertial>
      <pose>0.000000 0.000000 0.000000 0.000000 0.000000 0.000000</pose>
      <collision name="collision_0">
        <pose>-0.0018027756377319948 0.002 0 0.5880026035475675 1.57079 0</pose>
        <geometry>
          <cylinder>
            <radius>0.001</radius>
            <length>0.0036055512754639895</length>
          </cylinder>
        </geometry>
        <surface>
          <friction>
            <torsional>
              <coefficient>0.05</coefficient>
            </torsional>
            <bullet>
              <friction>0.05</friction>
              <friction2>0.05</friction2>
            </bullet>
          </friction>
        </surface>
      </collision>
      <visual name="visual_0">
        <pose>-0.0018027756377319948 0.002 0 0.5880026035475675 1.57079 0</pose>
        <geometry>
          <cylinder>
            <radius>0.001</radius>
            <length>0.0036055512754639895</length>
          </cylinder>
        </geometry>
        <material>
          <diffuse>1 0.219999999 0 1</diffuse>
          <specular>0.5 0.5 0.5 1</specular>
          <pbr>
            <metal>
              <roughness>0.01</roughness>
              <metalness>0.01</metalness>
            </metal>
          </pbr>
        </material>
      </visual>
      <collision name="collision_1">
        <pose>-0.0018027756377319948 -0.002 0 -0.5880026035475675 1.57079 0</pose>
        <geometry>
          <cylinder>
            <radius>0.001</radius>
            <length>0.0036055512754639895</length>
          </cylinder>
        </geometry>
        <surface>
          <friction>
            <torsional>
              <coefficient>0.05</coefficient>
            </torsional>
            <bullet>
              <friction>0.05</friction>
              <friction2>0.05</friction2>
            </bullet>
          </friction>
        </surface>
      </collision>
      <visual name="visual_1">
        <pose>-0.0018027756377319948 -0.002 0 -0.5880026035475675 1.57079 0</pose>
        <geometry>
          <cylinder>
            <radius>0.001</radius>
            <length>0.0036055512754639895</length>
          </cylinder>
        </geometry>
        <material>
          <diffuse>1 0.219999999 0 1</diffuse>
          <specular>0.5 0.5 0.5 1</specular>
          <pbr>
            <metal>
              <roughness>0.01</roughness>
              <metalness>0.01</metalness>
            </metal>
          </pbr>
        </material>
      </visual>
      <enable_wind>false</enable_wind>
    </link>
    <link name="cable_connection_1">
      <inertial>
        <pose>0 0 0 0 0 0</pose>
        <mass>0.01</mass>
        <inertia>
          <ixx>0.01</ixx>
          <ixy>0</ixy>
          <ixz>0</ixz>
          <iyy>0.01</iyy>
          <iyz>0</iyz>
          <izz>0.01</izz>
        </inertia>
      </inertial>
      <pose>0.960000 0.000000 0.000000 0.000000 0.000000 0.000000</pose>
      <collision name="collision_0">
        <pose>0.0036763602924631857 -0.00425 0 0.6162969373960713 1.57079 0</pose>
        <geometry>
          <cylinder>
            <radius>0.001</radius>
            <length>0.007352720584926371</length>
          </cylinder>
        </geometry>
        <surface>
          <friction>
            <torsional>
              <coefficient>0.05</coefficient>
            </torsional>
            <bullet>
              <friction>0.05</friction>
              <friction2>0.05</friction2>
            </bullet>
          </friction>
        </surface>
      </collision>
      <visual name="visual_0">
        <pose>0.0036763602924631857 -0.00425 0 0.6162969373960713 1.57079 0</pose>
        <geometry>
          <cylinder>
            <radius>0.001</radius>
            <length>0.007352720584926371</length>
          </cylinder>
        </geometry>
        <material>
          <diffuse>1 0.219999999 0 1</diffuse>
          <specular>0.5 0.5 0.5 1</specular>
          <pbr>
            <metal>
              <roughness>0.01</roughness>
              <metalness>0.01</metalness>
            </metal>
          </pbr>
        </material>
      </visual>
      <collision name="collision_1">
        <pose>0.0036763602924631857 0.00425 0 -0.6162969373960713 1.57079 0</pose>
        <geometry>
          <cylinder>
            <radius>0.001</radius>
            <length>0.007352720584926371</length>
          </cylinder>
        </geometry>
        <surface>
          <friction>
            <torsional>
              <coefficient>0.05</coefficient>
            </torsional>
            <bullet>
              <friction>0.05</friction>
              <friction2>0.05</friction2>
            </bullet>
          </friction>
        </surface>
      </collision>
      <visual name="visual_1">
        <pose>0.0036763602924631857 0.00425 0 -0.6162969373960713 1.57079 0</pose>
        <geometry>
          <cylinder>
            <radius>0.001</radius>
            <length>0.007352720584926371</length>
          </cylinder>
        </geometry>
        <material>
          <diffuse>1 0.219999999 0 1</diffuse>
          <specular>0.5 0.5 0.5 1</specular>
          <pbr>
            <metal>
              <roughness>0.01</roughness>
              <metalness>0.01</metalness>
            </metal>
          </pbr>
        </material>
      </visual>
      <enable_wind>false</enable_wind>
    </link>
    <joint name="joint_connection_end_0" type="ball">
      <pose>0.000000 0.000000 0.000000 0.000000 0.000000 0.000000</pose>
      <parent>cable_end_0</parent>
      <child>cable_connection_0</child>
      <axis>
        <xyz>1.3108744620427266e-16 -2.0816681711721685e-17 1</xyz>
        <limit>
          <lower>-inf</lower>
          <upper>inf</upper>
          <effort>inf</effort>
          <velocity>inf</velocity>
          <stiffness>100000000</stiffness>
          <dissipation>1</dissipation>
        </limit>
        <dynamics>
          <spring_reference>0</spring_reference>
          <spring_stiffness>0</spring_stiffness>
          <damping>0.2</damping>
          <friction>0</friction>
        </dynamics>
      </axis>
    </joint>
    <joint name="joint_connection_end_1" type="ball">
      <pose>0.000000 0.000000 0.000000 0.000000 0.000000 0.000000</pose>
      <parent>link_20</parent>
      <child>cable_connection_1</child>
      <axis>
        <xyz>4.1633363423443364e-17 -5.811323644522305e-17 1</xyz>
        <limit>
          <lower>-inf</lower>
          <upper>inf</upper>
          <effort>inf</effort>
          <velocity>inf</velocity>
          <stiffness>100000000</stiffness>
          <dissipation>1</dissipation>
        </limit>
        <dynamics>
          <spring_reference>0</spring_reference>
          <spring_stiffness>0</spring_stiffness>
          <damping>0.2</damping>
          <friction>0</friction>
        </dynamics>
      </axis>
    </joint>
  </model>
</sdf>